<?xml version="1.0"?>
<robot name="arm">

  <link name="base_link">
  </link>
  <link name="link1">
  </link>
  <link name="link2">
  </link>
  <link name="link3">
  </link>
  <link name="link4">
  </link>

 <joint name="base_link1" type="continuous">
    <parent link="base_link"/>
    <child link="link1"/>
    <axis xyz="0 0 1" />
    <origin rpy="0 0 0" xyz="0 0 0.25"/>
  </joint>

 <joint name="link1_link2" type="continuous">
    <parent link="link1"/>
    <child link="link2"/>
    <axis xyz="0 0 1" />
    <origin rpy="1.57 0 0" xyz="0 0 0.25"/>
  </joint>

<joint name="link2_link3" type="continuous">
    <parent link="link2"/>
    <child link="link3"/>
    <axis xyz="0 0 1" />
    <origin rpy="0 0 0" xyz="0.25 0 0"/>
  </joint>
<joint name="link3_link4" type="fixed">
    <parent link="link3"/>
    <child link="link4"/>
    <axis xyz="0 0 1" />
    <origin rpy="0 0 0" xyz="0.25 0 0"/>
  </joint>

</robot>

